Workbook
Name Slicer_Category: #N/A
Name Slicer_Customer_Location: #N/A
Name Slicer_Date_: #N/A
Name Slicer_Month: #N/A
Name Slicer_Payment_Method: #N/A
Name Slicer_Product: #N/A
Name Slicer_Status: #N/A
Name Slicer_Year: #N/A

Sheet Home

Sheet Raw_data
A1: Order ID | B1: Date | C1: Product | D1: Category | E1: Price | F1: Quantity | G1: Total Sales | H1: Customer Name | I1: Customer Location | J1: Payment Method | K1: Status
A2: ORD0001 | B2: 14-03-25 | C2: Running Shoes | D2: Footwear | E2: 60 | F2: 3 | G2: 180 | H2: Emma Clark | I2: New York | J2: Debit Card | K2: Cancelled
A3: ORD0002 | B3: 20-03-25 | C3: Headphones | D3: Electronics | E3: 100 | F3: 4 | G3: 400 | H3: Emily Johnson | I3: San Francisco | J3: Debit Card | K3: Pending
A4: ORD0003 | B4: 15-02-25 | C4: Running Shoes | D4: Footwear | E4: 60 | F4: 2 | G4: 120 | H4: John Doe | I4: Denver | J4: Amazon Pay | K4: Cancelled
A5: ORD0004 | B5: 19-02-25 | C5: Running Shoes | D5: Footwear | E5: 60 | F5: 3 | G5: 180 | H5: Olivia Wilson | I5: Dallas | J5: Credit Card | K5: Pending
A6: ORD0005 | B6: 45933 | C6: Smartwatch | D6: Electronics | E6: 150 | F6: 3 | G6: 450 | H6: Emma Clark | I6: New York | J6: Debit Card | K6: Pending
A7: ORD0006 | B7: 14-03-25 | C7: T-Shirt | D7: Clothing | E7: 20 | F7: 1 | G7: 20 | H7: John Doe | I7: Dallas | J7: Credit Card | K7: Pending
A8: ORD0007 | B8: 18-03-25 | C8: Smartwatch | D8: Electronics | E8: 150 | F8: 4 | G8: 600 | H8: Emma Clark | I8: Houston | J8: PayPal | K8: Completed
A9: ORD0008 | B9: 45691 | C9: Smartphone | D9: Electronics | E9: 500 | F9: 1 | G9: 500 | H9: Sophia Miller | I9: Miami | J9: PayPal | K9: Completed
A10: ORD0009 | B10: 45872 | C10: T-Shirt | D10: Clothing | E10: 20 | F10: 3 | G10: 60 | H10: Sophia Miller | I10: Boston | J10: PayPal | K10: Completed
A11: ORD0010 | B11: 45994 | C11: Smartphone | D11: Electronics | E11: 500 | F11: 1 | G11: 500 | H11: Emily Johnson | I11: San Francisco | J11: Credit Card | K11: Cancelled
A12: ORD0011 | B12: 17-02-25 | C12: Book | E12: 15 | F12: 2 | G12: 30 | H12: David Lee | I12: Boston | J12: Amazon Pay | K12: Pending
A13: ORD0012 | B13: 13-03-25 | C13: Jeans | D13: Clothing | E13: 40 | G13: 160 | H13: Michael Brown | I13: Dallas | J13: Credit Card | K13: Completed
A14: ORD0013 | B14: 45660 | D14: Electronics | F14: 2 | G14: 1600 | H14: Daniel Harris | I14: San Francisco | J14: Gift Card | K14: Pending
A15: ORD0014 | B15: 45750 | C15: Washing Machine | D15: Home Appliances | E15: 600 | F15: 3 | G15: 1800 | H15: Michael Brown | I15: Miami | J15: Credit Card | K15: Cancelled
A16: ORD0015 | B16: 20-02-25 | C16: Smartwatch | D16: Electronics | E16: 150 | F16: 4 | G16: 600 | H16: John Doe | I16: Seattle | J16: Credit Card | K16: Completed
A17: ORD0016 | B17: 26-02-25 | C17: Refrigerator | D17: Home Appliances | F17: 1 | G17: 1200 | H17: John Doe | I17: Boston | J17: Credit Card | K17: Cancelled
A18: ORD0017 | B18: 45661 | C18: T-Shirt | D18: Clothing | E18: 20 | F18: 1 | G18: 20 | H18: Emma Clark | I18: New York | J18: Amazon Pay | K18: Completed
A19: ORD0018 | B19: 45932 | C19: Smartphone | D19: Electronics | E19: 500 | F19: 2 | G19: 1000 | H19: Michael Brown | I19: Los Angeles | J19: Amazon Pay | K19: Completed
A20: ORD0019 | B20: 22-03-25 | C20: Running Shoes | D20: Footwear | E20: 60 | F20: 3 | G20: 180 | H20: Olivia Wilson | I20: Houston | J20: Credit Card | K20: Completed
A21: ORD0020 | B21: 45841 | C21: Headphones | D21: Electronics | E21: 100 | F21: 4 | G21: 400 | H21: Olivia Wilson | I21: Seattle | J21: Debit Card | K21: Pending
A22: ORD0021 | B22: 45779 | D22: Electronics | E22: 100 | F22: 3 | G22: 300 | H22: Chris White | I22: Miami | J22: Debit Card | K22: Cancelled
A23: ORD0022 | B23: 45841 | C23: Refrigerator | D23: Home Appliances | E23: 1200 | F23: 4 | G23: 4800 | H23: Olivia Wilson | I23: Houston | J23: Credit Card | K23: Pending
A24: ORD0023 | B24: 23-02-25 | C24: Book | D24: Books | E24: 15 | F24: 1 | G24: 15 | H24: Emma Clark | I24: Houston | J24: Credit Card | K24: Pending
A25: ORD0024 | B25: 24-03-25 | C25: Refrigerator | D25: Home Appliances | E25: 1200 | F25: 3 | G25: 3600 | H25: Chris White | I25: Dallas | J25: Credit Card | K25: Cancelled
A26: ORD0025 | B26: 45691 | C26: Book | D26: Books | E26: 15 | F26: 5 | G26: 75 | H26: Sophia Miller | I26: Seattle | J26: Amazon Pay | K26: Completed
A27: ORD0026 | B27: 14-02-25 | C27: Washing Machine | D27: Home Appliances | E27: 600 | F27: 1 | G27: 600 | H27: Olivia Wilson | I27: Boston | J27: Debit Card | K27: Cancelled
A28: ORD0027 | B28: 45840 | C28: T-Shirt | E28: 20 | G28: 20 | H28: Daniel Harris | I28: New York | J28: Amazon Pay | K28: Pending
A29: ORD0028 | B29: 45718 | C29: Headphones | D29: Electronics | E29: 100 | F29: 1 | G29: 100 | H29: Jane Smith | I29: Chicago | J29: Amazon Pay | K29: Completed
A30: ORD0029 | B30: 45993 | C30: Smartphone | D30: Electronics | E30: 500 | F30: 1 | G30: 500 | H30: Sophia Miller | I30: Denver | J30: Credit Card | K30: Cancelled
A31: ORD0030 | B31: 45932 | C31: Washing Machine | D31: Home Appliances | E31: 600 | F31: 3 | G31: 1800 | H31: Emily Johnson | I31: Dallas | J31: Gift Card | K31: Cancelled
A32: ORD0031 | B32: 24-03-25 | C32: Smartphone | D32: Electronics | F32: 1 | G32: 500 | H32: John Doe | I32: Houston | J32: Gift Card | K32: Pending
A33: ORD0032 | B33: 45933 | C33: Smartphone | D33: Electronics | E33: 500 | F33: 4 | G33: 2000 | H33: Michael Brown | I33: Seattle | J33: PayPal | K33: Pending
A34: ORD0033 | B34: 45749 | D34: Books | E34: 15 | F34: 1 | G34: 15 | H34: Olivia Wilson | I34: New York | J34: Debit Card | K34: Cancelled
A35: ORD0034 | B35: 45692 | C35: T-Shirt | D35: Clothing | E35: 20 | F35: 5 | G35: 100 | H35: Jane Smith | I35: New York | J35: Credit Card | K35: Pending
A36: ORD0035 | B36: 45692 | C36: Laptop | D36: Electronics | E36: 800 | F36: 3 | G36: 2400 | H36: Emma Clark | I36: Denver | J36: Amazon Pay | K36: Completed
A37: ORD0036 | B37: 45902 | C37: Refrigerator | D37: Home Appliances | E37: 1200 | F37: 2 | G37: 2400 | H37: Sophia Miller | I37: Boston | J37: PayPal | K37: Cancelled
A38: ORD0037 | B38: 16-02-25 | C38: Headphones | D38: Electronics | E38: 100 | F38: 3 | G38: 300 | H38: Michael Brown | I38: New York | J38: Debit Card | K38: Cancelled
A39: ORD0038 | B39: 26-03-25 | C39: Laptop | D39: Electronics | E39: 800 | F39: 3 | G39: 2400 | H39: Olivia Wilson | I39: Chicago | J39: Amazon Pay | K39: Completed
A40: ORD0039 | B40: 45691 | C40: Laptop | E40: 800 | F40: 2 | G40: 1600 | H40: Olivia Wilson | I40: San Francisco | J40: PayPal | K40: Completed
...

Sheet Cleanning_data
A1: Order ID | B1: Date | C1: Product | D1: Category | E1: Price | F1: Quantity | G1: Total Sales | H1: Customer Name | I1: Customer Location | J1: Payment Method | K1: Status | L1: Duplicate | M1: Date_text | N1: Date_ | O1: Month | P1: Year | R1: Columns | S1: NULL | T1: AVE | U1: MEDIAN | V1: MODE
A2: =IF(Raw_data!A2="",NA(),Raw_data!A2) -> ORD0001 | B2: =IF(Raw_data!B2="",NA(),Raw_data!B2) -> 14-03-25 | C2: =IF(Raw_data!C2="",NA(),Raw_data!C2) -> Running Shoes | D2: =IF(Raw_data!D2="",NA(),Raw_data!D2) -> Footwear | E2: =IF(Raw_data!E2="",NA(),Raw_data!E2) -> 60 | F2: =IF(Raw_data!F2="",NA(),Raw_data!F2) -> 3 | G2: =IF(Raw_data!G2="",NA(),Raw_data!G2) -> 180 | H2: =IF(Raw_data!H2="",NA(),Raw_data!H2) -> Emma Clark | ... K2: =IF(Raw_data!K2="",NA(),Raw_data!K2) -> Cancelled | L2: =COUNTIFS(A:A,A2,B:B,B2,C:C,C2,D:D,D2,E:E,E2,F:F,F2,G:G,G2,H:H,H2,I:I,I2,J:J,J2,K:K,K2) -> 1 | M2: =TEXT(B2,"dd-mm-yy") -> 14-03-25 | N2: =LEFT(Table2[[#This Row],[Date_text]],2) -> 14 | O2: =MID(Table2[[#This Row],[Date_text]],4,2) -> 03 | P2: =RIGHT(Table2[[#This Row],[Date_text]],2) -> 25 | R2: Order ID | S2: {=SUM(IF(Raw_data!A2:A255="",1,0))} -> 0
A3: =IF(Raw_data!A3="",NA(),Raw_data!A3) -> ORD0002 | B3: =IF(Raw_data!B3="",NA(),Raw_data!B3) -> 20-03-25 | C3: =IF(Raw_data!C3="",NA(),Raw_data!C3) -> Headphones | D3: =IF(Raw_data!D3="",NA(),Raw_data!D3) -> Electronics | E3: =IF(Raw_data!E3="",NA(),Raw_data!E3) -> 100 | F3: =IF(Raw_data!F3="",NA(),Raw_data!F3) -> 4 | G3: =IF(Raw_data!G3="",NA(),Raw_data!G3) -> 400 | H3: =IF(Raw_data!H3="",NA(),Raw_data!H3) -> Emily Johnson | ... K3: =IF(Raw_data!K3="",NA(),Raw_data!K3) -> Pending | L3: =COUNTIFS(A:A,A3,B:B,B3,C:C,C3,D:D,D3,E:E,E3,F:F,F3,G:G,G3,H:H,H3,I:I,I3,J:J,J3,K:K,K3) -> 1 | M3: =TEXT(B3,"dd-mm-yy") -> 20-03-25 | N3: =LEFT(Table2[[#This Row],[Date_text]],2) -> 20 | O3: =MID(Table2[[#This Row],[Date_text]],4,2) -> 03 | P3: =RIGHT(Table2[[#This Row],[Date_text]],2) -> 25 | R3: Date | S3: {=SUM(IF(Raw_data!B2:B255="",1,0))} -> 0
A4: =IF(Raw_data!A4="",NA(),Raw_data!A4) -> ORD0003 | B4: =IF(Raw_data!B4="",NA(),Raw_data!B4) -> 15-02-25 | C4: =IF(Raw_data!C4="",NA(),Raw_data!C4) -> Running Shoes | D4: =IF(Raw_data!D4="",NA(),Raw_data!D4) -> Footwear | E4: =IF(Raw_data!E4="",NA(),Raw_data!E4) -> 60 | F4: =IF(Raw_data!F4="",NA(),Raw_data!F4) -> 2 | G4: =IF(Raw_data!G4="",NA(),Raw_data!G4) -> 120 | H4: =IF(Raw_data!H4="",NA(),Raw_data!H4) -> John Doe | ... K4: =IF(Raw_data!K4="",NA(),Raw_data!K4) -> Cancelled | L4: =COUNTIFS(A:A,A4,B:B,B4,C:C,C4,D:D,D4,E:E,E4,F:F,F4,G:G,G4,H:H,H4,I:I,I4,J:J,J4,K:K,K4) -> 1 | M4: =TEXT(B4,"dd-mm-yy") -> 15-02-25 | N4: =LEFT(Table2[[#This Row],[Date_text]],2) -> 15 | O4: =MID(Table2[[#This Row],[Date_text]],4,2) -> 02 | P4: =RIGHT(Table2[[#This Row],[Date_text]],2) -> 25 | R4: Product | S4: {=SUM(IF(Raw_data!C2:C255="",1,0))} -> 21 | V4: Smartwatch
A5: =IF(Raw_data!A5="",NA(),Raw_data!A5) -> ORD0004 | B5: =IF(Raw_data!B5="",NA(),Raw_data!B5) -> 19-02-25 | C5: =IF(Raw_data!C5="",NA(),Raw_data!C5) -> Running Shoes | D5: =IF(Raw_data!D5="",NA(),Raw_data!D5) -> Footwear | E5: =IF(Raw_data!E5="",NA(),Raw_data!E5) -> 60 | F5: =IF(Raw_data!F5="",NA(),Raw_data!F5) -> 3 | G5: =IF(Raw_data!G5="",NA(),Raw_data!G5) -> 180 | H5: =IF(Raw_data!H5="",NA(),Raw_data!H5) -> Olivia Wilson | ... K5: =IF(Raw_data!K5="",NA(),Raw_data!K5) -> Pending | L5: =COUNTIFS(A:A,A5,B:B,B5,C:C,C5,D:D,D5,E:E,E5,F:F,F5,G:G,G5,H:H,H5,I:I,I5,J:J,J5,K:K,K5) -> 1 | M5: =TEXT(B5,"dd-mm-yy") -> 19-02-25 | N5: =LEFT(Table2[[#This Row],[Date_text]],2) -> 19 | O5: =MID(Table2[[#This Row],[Date_text]],4,2) -> 02 | P5: =RIGHT(Table2[[#This Row],[Date_text]],2) -> 25 | R5: Category | S5: {=SUM(IF(Raw_data!D2:D255="",1,0))} -> 14 | V5: Electronics
A6: =IF(Raw_data!A6="",NA(),Raw_data!A6) -> ORD0005 | B6: =IF(Raw_data!B6="",NA(),Raw_data!B6) -> 45933 | C6: =IF(Raw_data!C6="",NA(),Raw_data!C6) -> Smartwatch | D6: =IF(Raw_data!D6="",NA(),Raw_data!D6) -> Electronics | E6: =IF(Raw_data!E6="",NA(),Raw_data!E6) -> 150 | F6: =IF(Raw_data!F6="",NA(),Raw_data!F6) -> 3 | G6: =IF(Raw_data!G6="",NA(),Raw_data!G6) -> 450 | H6: =IF(Raw_data!H6="",NA(),Raw_data!H6) -> Emma Clark | ... K6: =IF(Raw_data!K6="",NA(),Raw_data!K6) -> Pending | L6: =COUNTIFS(A:A,A6,B:B,B6,C:C,C6,D:D,D6,E:E,E6,F:F,F6,G:G,G6,H:H,H6,I:I,I6,J:J,J6,K:K,K6) -> 1 | M6: =TEXT(B6,"dd-mm-yy") -> 03-10-25 | N6: =LEFT(Table2[[#This Row],[Date_text]],2) -> 03 | O6: =MID(Table2[[#This Row],[Date_text]],4,2) -> 10 | P6: =RIGHT(Table2[[#This Row],[Date_text]],2) -> 25 | R6: Price | S6: {=SUM(IF(Raw_data!E2:E255="",1,0))} -> 17 | T6: =_xlfn.AGGREGATE(1,6,Raw_data!E1:E255) -> 334.70464 | U6: =_xlfn.AGGREGATE(12,6,Raw_data!E1:E255) -> 150
A7: =IF(Raw_data!A7="",NA(),Raw_data!A7) -> ORD0006 | B7: =IF(Raw_data!B7="",NA(),Raw_data!B7) -> 14-03-25 | C7: =IF(Raw_data!C7="",NA(),Raw_data!C7) -> T-Shirt | D7: =IF(Raw_data!D7="",NA(),Raw_data!D7) -> Clothing | E7: =IF(Raw_data!E7="",NA(),Raw_data!E7) -> 20 | F7: =IF(Raw_data!F7="",NA(),Raw_data!F7) -> 1 | G7: =IF(Raw_data!G7="",NA(),Raw_data!G7) -> 20 | H7: =IF(Raw_data!H7="",NA(),Raw_data!H7) -> John Doe | ... K7: =IF(Raw_data!K7="",NA(),Raw_data!K7) -> Pending | L7: =COUNTIFS(A:A,A7,B:B,B7,C:C,C7,D:D,D7,E:E,E7,F:F,F7,G:G,G7,H:H,H7,I:I,I7,J:J,J7,K:K,K7) -> 1 | M7: =TEXT(B7,"dd-mm-yy") -> 14-03-25 | N7: =LEFT(Table2[[#This Row],[Date_text]],2) -> 14 | O7: =MID(Table2[[#This Row],[Date_text]],4,2) -> 03 | P7: =RIGHT(Table2[[#This Row],[Date_text]],2) -> 25 | R7: Quantity | S7: {=SUM(IF(Raw_data!F2:F255="",1,0))} -> 16 | T7: =_xlfn.AGGREGATE(1,6,Raw_data!F1:F255) -> 2.8781513 | U7: =_xlfn.AGGREGATE(12,6,Raw_data!F1:F255) -> 3
A8: =IF(Raw_data!A8="",NA(),Raw_data!A8) -> ORD0007 | B8: =IF(Raw_data!B8="",NA(),Raw_data!B8) -> 18-03-25 | C8: =IF(Raw_data!C8="",NA(),Raw_data!C8) -> Smartwatch | D8: =IF(Raw_data!D8="",NA(),Raw_data!D8) -> Electronics | E8: =IF(Raw_data!E8="",NA(),Raw_data!E8) -> 150 | F8: =IF(Raw_data!F8="",NA(),Raw_data!F8) -> 4 | G8: =IF(Raw_data!G8="",NA(),Raw_data!G8) -> 600 | H8: =IF(Raw_data!H8="",NA(),Raw_data!H8) -> Emma Clark | ... K8: =IF(Raw_data!K8="",NA(),Raw_data!K8) -> Completed | L8: =COUNTIFS(A:A,A8,B:B,B8,C:C,C8,D:D,D8,E:E,E8,F:F,F8,G:G,G8,H:H,H8,I:I,I8,J:J,J8,K:K,K8) -> 1 | M8: =TEXT(B8,"dd-mm-yy") -> 18-03-25 | N8: =LEFT(Table2[[#This Row],[Date_text]],2) -> 18 | O8: =MID(Table2[[#This Row],[Date_text]],4,2) -> 03 | P8: =RIGHT(Table2[[#This Row],[Date_text]],2) -> 25 | R8: Total Sales | S8: {=SUM(IF(Raw_data!G2:G255="",1,0))} -> 0 | T8: =_xlfn.AGGREGATE(1,6,Raw_data!G1:G255) -> 991.51575 | U8: =_xlfn.AGGREGATE(12,6,Raw_data!G1:G255) -> 400
A9: =IF(Raw_data!A9="",NA(),Raw_data!A9) -> ORD0008 | B9: =IF(Raw_data!B9="",NA(),Raw_data!B9) -> 45691 | C9: =IF(Raw_data!C9="",NA(),Raw_data!C9) -> Smartphone | D9: =IF(Raw_data!D9="",NA(),Raw_data!D9) -> Electronics | E9: =IF(Raw_data!E9="",NA(),Raw_data!E9) -> 500 | F9: =IF(Raw_data!F9="",NA(),Raw_data!F9) -> 1 | G9: =IF(Raw_data!G9="",NA(),Raw_data!G9) -> 500 | H9: =IF(Raw_data!H9="",NA(),Raw_data!H9) -> Sophia Miller | ... K9: =IF(Raw_data!K9="",NA(),Raw_data!K9) -> Completed | L9: =COUNTIFS(A:A,A9,B:B,B9,C:C,C9,D:D,D9,E:E,E9,F:F,F9,G:G,G9,H:H,H9,I:I,I9,J:J,J9,K:K,K9) -> 1 | M9: =TEXT(B9,"dd-mm-yy") -> 03-02-25 | N9: =LEFT(Table2[[#This Row],[Date_text]],2) -> 03 | O9: =MID(Table2[[#This Row],[Date_text]],4,2) -> 02 | P9: =RIGHT(Table2[[#This Row],[Date_text]],2) -> 25 | R9: Customer Name | S9: {=SUM(IF(Raw_data!H2:H255="",1,0))} -> 0
A10: =IF(Raw_data!A10="",NA(),Raw_data!A10) -> ORD0009 | B10: =IF(Raw_data!B10="",NA(),Raw_data!B10) -> 45872 | C10: =IF(Raw_data!C10="",NA(),Raw_data!C10) -> T-Shirt | D10: =IF(Raw_data!D10="",NA(),Raw_data!D10) -> Clothing | E10: =IF(Raw_data!E10="",NA(),Raw_data!E10) -> 20 | F10: =IF(Raw_data!F10="",NA(),Raw_data!F10) -> 3 | G10: =IF(Raw_data!G10="",NA(),Raw_data!G10) -> 60 | H10: =IF(Raw_data!H10="",NA(),Raw_data!H10) -> Sophia Miller | ... K10: =IF(Raw_data!K10="",NA(),Raw_data!K10) -> Completed | L10: =COUNTIFS(A:A,A10,B:B,B10,C:C,C10,D:D,D10,E:E,E10,F:F,F10,G:G,G10,H:H,H10,I:I,I10,J:J,J10,K:K,K10) -> 1 | M10: =TEXT(B10,"dd-mm-yy") -> 03-08-25 | N10: =LEFT(Table2[[#This Row],[Date_text]],2) -> 03 | O10: =MID(Table2[[#This Row],[Date_text]],4,2) -> 08 | P10: =RIGHT(Table2[[#This Row],[Date_text]],2) -> 25 | R10: Customer Location | S10: {=SUM(IF(Raw_data!I2:I255="",1,0))} -> 11 | V10: Miami
A11: =IF(Raw_data!A11="",NA(),Raw_data!A11) -> ORD0010 | B11: =IF(Raw_data!B11="",NA(),Raw_data!B11) -> 45994 | C11: =IF(Raw_data!C11="",NA(),Raw_data!C11) -> Smartphone | D11: =IF(Raw_data!D11="",NA(),Raw_data!D11) -> Electronics | E11: =IF(Raw_data!E11="",NA(),Raw_data!E11) -> 500 | F11: =IF(Raw_data!F11="",NA(),Raw_data!F11) -> 1 | G11: =IF(Raw_data!G11="",NA(),Raw_data!G11) -> 500 | H11: =IF(Raw_data!H11="",NA(),Raw_data!H11) -> Emily Johnson | ... K11: =IF(Raw_data!K11="",NA(),Raw_data!K11) -> Cancelled | L11: =COUNTIFS(A:A,A11,B:B,B11,C:C,C11,D:D,D11,E:E,E11,F:F,F11,G:G,G11,H:H,H11,I:I,I11,J:J,J11,K:K,K11) -> 1 | M11: =TEXT(B11,"dd-mm-yy") -> 03-12-25 | N11: =LEFT(Table2[[#This Row],[Date_text]],2) -> 03 | O11: =MID(Table2[[#This Row],[Date_text]],4,2) -> 12 | P11: =RIGHT(Table2[[#This Row],[Date_text]],2) -> 25 | R11: Payment Method | S11: {=SUM(IF(Raw_data!J2:J255="",1,0))} -> 0
A12: =IF(Raw_data!A12="",NA(),Raw_data!A12) -> ORD0011 | B12: =IF(Raw_data!B12="",NA(),Raw_data!B12) -> 17-02-25 | C12: =IF(Raw_data!C12="",NA(),Raw_data!C12) -> Book | D12: Electronics | E12: =IF(Raw_data!E12="",NA(),Raw_data!E12) -> 15 | F12: =IF(Raw_data!F12="",NA(),Raw_data!F12) -> 2 | G12: =IF(Raw_data!G12="",NA(),Raw_data!G12) -> 30 | H12: =IF(Raw_data!H12="",NA(),Raw_data!H12) -> David Lee | I12: =IF(Raw_data!I12="",NA(),Raw_data!I12) -> Boston | J12: =IF(Raw_data!J12="",NA(),Raw_data!J12) -> Amazon Pay | K12: =IF(Raw_data!K12="",NA(),Raw_data!K12) -> Pending | L12: =COUNTIFS(A:A,A12,B:B,B12,C:C,C12,D:D,D12,E:E,E12,F:F,F12,G:G,G12,H:H,H12,I:I,I12,J:J,J12,K:K,K12) -> 1 | M12: =TEXT(B12,"dd-mm-yy") -> 17-02-25 | N12: =LEFT(Table2[[#This Row],[Date_text]],2) -> 17 | O12: =MID(Table2[[#This Row],[Date_text]],4,2) -> 02 | P12: =RIGHT(Table2[[#This Row],[Date_text]],2) -> 25 | R12: Status | S12: {=SUM(IF(Raw_data!K2:K255="",1,0))} -> 0
A13: =IF(Raw_data!A13="",NA(),Raw_data!A13) -> ORD0012 | B13: =IF(Raw_data!B13="",NA(),Raw_data!B13) -> 13-03-25 | C13: =IF(Raw_data!C13="",NA(),Raw_data!C13) -> Jeans | D13: =IF(Raw_data!D13="",NA(),Raw_data!D13) -> Clothing | E13: =IF(Raw_data!E13="",NA(),Raw_data!E13) -> 40 | F13: 3 | G13: =IF(Raw_data!G13="",NA(),Raw_data!G13) -> 160 | H13: =IF(Raw_data!H13="",NA(),Raw_data!H13) -> Michael Brown | I13: =IF(Raw_data!I13="",NA(),Raw_data!I13) -> Dallas | J13: =IF(Raw_data!J13="",NA(),Raw_data!J13) -> Credit Card | K13: =IF(Raw_data!K13="",NA(),Raw_data!K13) -> Completed | L13: =COUNTIFS(A:A,A13,B:B,B13,C:C,C13,D:D,D13,E:E,E13,F:F,F13,G:G,G13,H:H,H13,I:I,I13,J:J,J13,K:K,K13) -> 1 | M13: =TEXT(B13,"dd-mm-yy") -> 13-03-25 | N13: =LEFT(Table2[[#This Row],[Date_text]],2) -> 13 | O13: =MID(Table2[[#This Row],[Date_text]],4,2) -> 03 | P13: =RIGHT(Table2[[#This Row],[Date_text]],2) -> 25
A14: =IF(Raw_data!A15="",NA(),Raw_data!A15) -> ORD0014 | B14: =IF(Raw_data!B15="",NA(),Raw_data!B15) -> 45750 | C14: =IF(Raw_data!C15="",NA(),Raw_data!C15) -> Washing Machine | D14: =IF(Raw_data!D15="",NA(),Raw_data!D15) -> Home Appliances | E14: =IF(Raw_data!E15="",NA(),Raw_data!E15) -> 600 | F14: =IF(Raw_data!F15="",NA(),Raw_data!F15) -> 3 | G14: =IF(Raw_data!G15="",NA(),Raw_data!G15) -> 1800 | H14: =IF(Raw_data!H15="",NA(),Raw_data!H15) -> Michael Brown | ... K14: =IF(Raw_data!K15="",NA(),Raw_data!K15) -> Cancelled | L14: =COUNTIFS(A:A,A14,B:B,B14,C:C,C14,D:D,D14,E:E,E14,F:F,F14,G:G,G14,H:H,H14,I:I,I14,J:J,J14,K:K,K14) -> 1 | M14: =TEXT(B14,"dd-mm-yy") -> 03-04-25 | N14: =LEFT(Table2[[#This Row],[Date_text]],2) -> 03 | O14: =MID(Table2[[#This Row],[Date_text]],4,2) -> 04 | P14: =RIGHT(Table2[[#This Row],[Date_text]],2) -> 25 | R14: PRODUCT | S14: Column1 | U14: CATEGORY | V14: Column1 | X14: LOCATION | Y14: Column1
A15: =IF(Raw_data!A16="",NA(),Raw_data!A16) -> ORD0015 | B15: =IF(Raw_data!B16="",NA(),Raw_data!B16) -> 20-02-25 | C15: =IF(Raw_data!C16="",NA(),Raw_data!C16) -> Smartwatch | D15: =IF(Raw_data!D16="",NA(),Raw_data!D16) -> Electronics | E15: =IF(Raw_data!E16="",NA(),Raw_data!E16) -> 150 | F15: =IF(Raw_data!F16="",NA(),Raw_data!F16) -> 4 | G15: =IF(Raw_data!G16="",NA(),Raw_data!G16) -> 600 | H15: =IF(Raw_data!H16="",NA(),Raw_data!H16) -> John Doe | ... K15: =IF(Raw_data!K16="",NA(),Raw_data!K16) -> Completed | L15: =COUNTIFS(A:A,A15,B:B,B15,C:C,C15,D:D,D15,E:E,E15,F:F,F15,G:G,G15,H:H,H15,I:I,I15,J:J,J15,K:K,K15) -> 1 | M15: =TEXT(B15,"dd-mm-yy") -> 20-02-25 | N15: =LEFT(Table2[[#This Row],[Date_text]],2) -> 20 | O15: =MID(Table2[[#This Row],[Date_text]],4,2) -> 02 | P15: =RIGHT(Table2[[#This Row],[Date_text]],2) -> 25 | R15: {=_xlfn.UNIQUE(Raw_data!C2:C255)} -> Running Shoes | S15: =COUNTIF(Raw_data!C2:C255,R15) -> 27 | U15: {=_xlfn.UNIQUE(Raw_data!D2:D255)} -> Footwear | V15: =COUNTIF(Raw_data!D2:D255,U15) -> 25 | X15: {=_xlfn.UNIQUE(Raw_data!I2:I255)} -> New York | Y15: =COUNTIF(Raw_data!I2:I255,X15) -> 24
A16: =IF(Raw_data!A17="",NA(),Raw_data!A17) -> ORD0016 | B16: =IF(Raw_data!B17="",NA(),Raw_data!B17) -> 26-02-25 | C16: =IF(Raw_data!C17="",NA(),Raw_data!C17) -> Refrigerator | D16: =IF(Raw_data!D17="",NA(),Raw_data!D17) -> Home Appliances | E16: 150 | F16: =IF(Raw_data!F17="",NA(),Raw_data!F17) -> 1 | G16: =IF(Raw_data!G17="",NA(),Raw_data!G17) -> 1200 | H16: =IF(Raw_data!H17="",NA(),Raw_data!H17) -> John Doe | I16: =IF(Raw_data!I17="",NA(),Raw_data!I17) -> Boston | J16: =IF(Raw_data!J17="",NA(),Raw_data!J17) -> Credit Card | K16: =IF(Raw_data!K17="",NA(),Raw_data!K17) -> Cancelled | L16: =COUNTIFS(A:A,A16,B:B,B16,C:C,C16,D:D,D16,E:E,E16,F:F,F16,G:G,G16,H:H,H16,I:I,I16,J:J,J16,K:K,K16) -> 1 | M16: =TEXT(B16,"dd-mm-yy") -> 26-02-25 | N16: =LEFT(Table2[[#This Row],[Date_text]],2) -> 26 | O16: =MID(Table2[[#This Row],[Date_text]],4,2) -> 02 | P16: =RIGHT(Table2[[#This Row],[Date_text]],2) -> 25 | R16: Headphones | S16: =COUNTIF(Raw_data!C3:C256,R16) -> 22 | U16: Electronics | V16: =COUNTIF(Raw_data!D3:D256,U16) -> 118 | X16: San Francisco | Y16: =COUNTIF(Raw_data!I3:I256,X16) -> 19
A17: =IF(Raw_data!A18="",NA(),Raw_data!A18) -> ORD0017 | B17: =IF(Raw_data!B18="",NA(),Raw_data!B18) -> 45661 | C17: =IF(Raw_data!C18="",NA(),Raw_data!C18) -> T-Shirt | D17: =IF(Raw_data!D18="",NA(),Raw_data!D18) -> Clothing | E17: =IF(Raw_data!E18="",NA(),Raw_data!E18) -> 20 | F17: =IF(Raw_data!F18="",NA(),Raw_data!F18) -> 1 | G17: =IF(Raw_data!G18="",NA(),Raw_data!G18) -> 20 | H17: =IF(Raw_data!H18="",NA(),Raw_data!H18) -> Emma Clark | ... K17: =IF(Raw_data!K18="",NA(),Raw_data!K18) -> Completed | L17: =COUNTIFS(A:A,A17,B:B,B17,C:C,C17,D:D,D17,E:E,E17,F:F,F17,G:G,G17,H:H,H17,I:I,I17,J:J,J17,K:K,K17) -> 1 | M17: =TEXT(B17,"dd-mm-yy") -> 04-01-25 | N17: =LEFT(Table2[[#This Row],[Date_text]],2) -> 04 | O17: =MID(Table2[[#This Row],[Date_text]],4,2) -> 01 | P17: =RIGHT(Table2[[#This Row],[Date_text]],2) -> 25 | R17: Smartwatch | S17: =COUNTIF(Raw_data!C4:C257,R17) -> 33 | U17: Clothing | V17: =COUNTIF(Raw_data!D4:D257,U17) -> 37 | X17: Denver | Y17: =COUNTIF(Raw_data!I4:I257,X17) -> 26
A18: =IF(Raw_data!A19="",NA(),Raw_data!A19) -> ORD0018 | B18: =IF(Raw_data!B19="",NA(),Raw_data!B19) -> 45932 | C18: =IF(Raw_data!C19="",NA(),Raw_data!C19) -> Smartphone | D18: =IF(Raw_data!D19="",NA(),Raw_data!D19) -> Electronics | E18: =IF(Raw_data!E19="",NA(),Raw_data!E19) -> 500 | F18: =IF(Raw_data!F19="",NA(),Raw_data!F19) -> 2 | G18: =IF(Raw_data!G19="",NA(),Raw_data!G19) -> 1000 | H18: =IF(Raw_data!H19="",NA(),Raw_data!H19) -> Michael Brown | ... K18: =IF(Raw_data!K19="",NA(),Raw_data!K19) -> Completed | L18: =COUNTIFS(A:A,A18,B:B,B18,C:C,C18,D:D,D18,E:E,E18,F:F,F18,G:G,G18,H:H,H18,I:I,I18,J:J,J18,K:K,K18) -> 1 | M18: =TEXT(B18,"dd-mm-yy") -> 02-10-25 | N18: =LEFT(Table2[[#This Row],[Date_text]],2) -> 02 | O18: =MID(Table2[[#This Row],[Date_text]],4,2) -> 10 | P18: =RIGHT(Table2[[#This Row],[Date_text]],2) -> 25 | R18: T-Shirt | S18: =COUNTIF(Raw_data!C5:C258,R18) -> 20 | U18: 0 | V18: =COUNTIF(Raw_data!D5:D258,U18) -> 0 | X18: Dallas | Y18: =COUNTIF(Raw_data!I5:I258,X18) -> 27
A19: =IF(Raw_data!A20="",NA(),Raw_data!A20) -> ORD0019 | B19: =IF(Raw_data!B20="",NA(),Raw_data!B20) -> 22-03-25 | C19: =IF(Raw_data!C20="",NA(),Raw_data!C20) -> Running Shoes | D19: =IF(Raw_data!D20="",NA(),Raw_data!D20) -> Footwear | E19: =IF(Raw_data!E20="",NA(),Raw_data!E20) -> 60 | F19: =IF(Raw_data!F20="",NA(),Raw_data!F20) -> 3 | G19: =IF(Raw_data!G20="",NA(),Raw_data!G20) -> 180 | H19: =IF(Raw_data!H20="",NA(),Raw_data!H20) -> Olivia Wilson | ... K19: =IF(Raw_data!K20="",NA(),Raw_data!K20) -> Completed | L19: =COUNTIFS(A:A,A19,B:B,B19,C:C,C19,D:D,D19,E:E,E19,F:F,F19,G:G,G19,H:H,H19,I:I,I19,J:J,J19,K:K,K19) -> 1 | M19: =TEXT(B19,"dd-mm-yy") -> 22-03-25 | N19: =LEFT(Table2[[#This Row],[Date_text]],2) -> 22 | O19: =MID(Table2[[#This Row],[Date_text]],4,2) -> 03 | P19: =RIGHT(Table2[[#This Row],[Date_text]],2) -> 25 | R19: Smartphone | S19: =COUNTIF(Raw_data!C6:C259,R19) -> 35 | U19: Home Appliances | V19: =COUNTIF(Raw_data!D6:D259,U19) -> 37 | X19: Houston | Y19: =COUNTIF(Raw_data!I6:I259,X19) -> 29
A20: =IF(Raw_data!A21="",NA(),Raw_data!A21) -> ORD0020 | B20: =IF(Raw_data!B21="",NA(),Raw_data!B21) -> 45841 | C20: =IF(Raw_data!C21="",NA(),Raw_data!C21) -> Headphones | D20: =IF(Raw_data!D21="",NA(),Raw_data!D21) -> Electronics | E20: =IF(Raw_data!E21="",NA(),Raw_data!E21) -> 100 | F20: =IF(Raw_data!F21="",NA(),Raw_data!F21) -> 4 | G20: =IF(Raw_data!G21="",NA(),Raw_data!G21) -> 400 | H20: =IF(Raw_data!H21="",NA(),Raw_data!H21) -> Olivia Wilson | ... K20: =IF(Raw_data!K21="",NA(),Raw_data!K21) -> Pending | L20: =COUNTIFS(A:A,A20,B:B,B20,C:C,C20,D:D,D20,E:E,E20,F:F,F20,G:G,G20,H:H,H20,I:I,I20,J:J,J20,K:K,K20) -> 1 | M20: =TEXT(B20,"dd-mm-yy") -> 03-07-25 | N20: =LEFT(Table2[[#This Row],[Date_text]],2) -> 03 | O20: =MID(Table2[[#This Row],[Date_text]],4,2) -> 07 | P20: =RIGHT(Table2[[#This Row],[Date_text]],2) -> 25 | R20: Book | S20: =COUNTIF(Raw_data!C7:C260,R20) -> 23 | U20: Books | V20: =COUNTIF(Raw_data!D7:D260,U20) -> 23 | X20: Miami | Y20: =COUNTIF(Raw_data!I7:I260,X20) -> 30
A21: =IF(Raw_data!A23="",NA(),Raw_data!A23) -> ORD0022 | B21: =IF(Raw_data!B23="",NA(),Raw_data!B23) -> 45841 | C21: =IF(Raw_data!C23="",NA(),Raw_data!C23) -> Refrigerator | D21: =IF(Raw_data!D23="",NA(),Raw_data!D23) -> Home Appliances | E21: =IF(Raw_data!E23="",NA(),Raw_data!E23) -> 1200 | F21: =IF(Raw_data!F23="",NA(),Raw_data!F23) -> 4 | G21: =IF(Raw_data!G23="",NA(),Raw_data!G23) -> 4800 | H21: =IF(Raw_data!H23="",NA(),Raw_data!H23) -> Olivia Wilson | ... K21: =IF(Raw_data!K23="",NA(),Raw_data!K23) -> Pending | L21: =COUNTIFS(A:A,A21,B:B,B21,C:C,C21,D:D,D21,E:E,E21,F:F,F21,G:G,G21,H:H,H21,I:I,I21,J:J,J21,K:K,K21) -> 1 | M21: =TEXT(B21,"dd-mm-yy") -> 03-07-25 | N21: =LEFT(Table2[[#This Row],[Date_text]],2) -> 03 | O21: =MID(Table2[[#This Row],[Date_text]],4,2) -> 07 | P21: =RIGHT(Table2[[#This Row],[Date_text]],2) -> 25 | R21: Jeans | S21: =COUNTIF(Raw_data!C8:C261,R21) -> 16 | X21: Boston | Y21: =COUNTIF(Raw_data!I8:I261,X21) -> 29
A22: =IF(Raw_data!A24="",NA(),Raw_data!A24) -> ORD0023 | B22: =IF(Raw_data!B24="",NA(),Raw_data!B24) -> 23-02-25 | C22: =IF(Raw_data!C24="",NA(),Raw_data!C24) -> Book | D22: =IF(Raw_data!D24="",NA(),Raw_data!D24) -> Books | E22: =IF(Raw_data!E24="",NA(),Raw_data!E24) -> 15 | F22: =IF(Raw_data!F24="",NA(),Raw_data!F24) -> 1 | G22: =IF(Raw_data!G24="",NA(),Raw_data!G24) -> 15 | H22: =IF(Raw_data!H24="",NA(),Raw_data!H24) -> Emma Clark | ... K22: =IF(Raw_data!K24="",NA(),Raw_data!K24) -> Pending | L22: =COUNTIFS(A:A,A22,B:B,B22,C:C,C22,D:D,D22,E:E,E22,F:F,F22,G:G,G22,H:H,H22,I:I,I22,J:J,J22,K:K,K22) -> 1 | M22: =TEXT(B22,"dd-mm-yy") -> 23-02-25 | N22: =LEFT(Table2[[#This Row],[Date_text]],2) -> 23 | O22: =MID(Table2[[#This Row],[Date_text]],4,2) -> 02 | P22: =RIGHT(Table2[[#This Row],[Date_text]],2) -> 25 | R22: 0 | S22: =COUNTIF(Raw_data!C9:C262,R22) -> 0 | X22: Seattle | Y22: =COUNTIF(Raw_data!I9:I262,X22) -> 22
A23: =IF(Raw_data!A25="",NA(),Raw_data!A25) -> ORD0024 | B23: =IF(Raw_data!B25="",NA(),Raw_data!B25) -> 24-03-25 | C23: =IF(Raw_data!C25="",NA(),Raw_data!C25) -> Refrigerator | D23: =IF(Raw_data!D25="",NA(),Raw_data!D25) -> Home Appliances | E23: =IF(Raw_data!E25="",NA(),Raw_data!E25) -> 1200 | F23: =IF(Raw_data!F25="",NA(),Raw_data!F25) -> 3 | G23: =IF(Raw_data!G25="",NA(),Raw_data!G25) -> 3600 | H23: =IF(Raw_data!H25="",NA(),Raw_data!H25) -> Chris White | ... K23: =IF(Raw_data!K25="",NA(),Raw_data!K25) -> Cancelled | L23: =COUNTIFS(A:A,A23,B:B,B23,C:C,C23,D:D,D23,E:E,E23,F:F,F23,G:G,G23,H:H,H23,I:I,I23,J:J,J23,K:K,K23) -> 1 | M23: =TEXT(B23,"dd-mm-yy") -> 24-03-25 | N23: =LEFT(Table2[[#This Row],[Date_text]],2) -> 24 | O23: =MID(Table2[[#This Row],[Date_text]],4,2) -> 03 | P23: =RIGHT(Table2[[#This Row],[Date_text]],2) -> 25 | R23: Washing Machine | S23: =COUNTIF(Raw_data!C10:C263,R23) -> 15 | X23: Los Angeles | Y23: =COUNTIF(Raw_data!I10:I263,X23) -> 17
A24: =IF(Raw_data!A26="",NA(),Raw_data!A26) -> ORD0025 | B24: =IF(Raw_data!B26="",NA(),Raw_data!B26) -> 45691 | C24: =IF(Raw_data!C26="",NA(),Raw_data!C26) -> Book | D24: =IF(Raw_data!D26="",NA(),Raw_data!D26) -> Books | E24: =IF(Raw_data!E26="",NA(),Raw_data!E26) -> 15 | F24: =IF(Raw_data!F26="",NA(),Raw_data!F26) -> 5 | G24: =IF(Raw_data!G26="",NA(),Raw_data!G26) -> 75 | H24: =IF(Raw_data!H26="",NA(),Raw_data!H26) -> Sophia Miller | ... K24: =IF(Raw_data!K26="",NA(),Raw_data!K26) -> Completed | L24: =COUNTIFS(A:A,A24,B:B,B24,C:C,C24,D:D,D24,E:E,E24,F:F,F24,G:G,G24,H:H,H24,I:I,I24,J:J,J24,K:K,K24) -> 1 | M24: =TEXT(B24,"dd-mm-yy") -> 03-02-25 | N24: =LEFT(Table2[[#This Row],[Date_text]],2) -> 03 | O24: =MID(Table2[[#This Row],[Date_text]],4,2) -> 02 | P24: =RIGHT(Table2[[#This Row],[Date_text]],2) -> 25 | R24: Refrigerator | S24: =COUNTIF(Raw_data!C11:C264,R24) -> 20 | X24: Chicago | Y24: =COUNTIF(Raw_data!I11:I264,X24) -> 20
A25: =IF(Raw_data!A27="",NA(),Raw_data!A27) -> ORD0026 | B25: =IF(Raw_data!B27="",NA(),Raw_data!B27) -> 14-02-25 | C25: =IF(Raw_data!C27="",NA(),Raw_data!C27) -> Washing Machine | D25: =IF(Raw_data!D27="",NA(),Raw_data!D27) -> Home Appliances | E25: =IF(Raw_data!E27="",NA(),Raw_data!E27) -> 600 | F25: =IF(Raw_data!F27="",NA(),Raw_data!F27) -> 1 | G25: =IF(Raw_data!G27="",NA(),Raw_data!G27) -> 600 | H25: =IF(Raw_data!H27="",NA(),Raw_data!H27) -> Olivia Wilson | ... K25: =IF(Raw_data!K27="",NA(),Raw_data!K27) -> Cancelled | L25: =COUNTIFS(A:A,A25,B:B,B25,C:C,C25,D:D,D25,E:E,E25,F:F,F25,G:G,G25,H:H,H25,I:I,I25,J:J,J25,K:K,K25) -> 1 | M25: =TEXT(B25,"dd-mm-yy") -> 14-02-25 | N25: =LEFT(Table2[[#This Row],[Date_text]],2) -> 14 | O25: =MID(Table2[[#This Row],[Date_text]],4,2) -> 02 | P25: =RIGHT(Table2[[#This Row],[Date_text]],2) -> 25 | R25: Laptop | S25: =COUNTIF(Raw_data!C12:C265,R25) -> 22 | X25: 0 | Y25: =COUNTIF(Raw_data!I12:I265,X25) -> 0
A26: =IF(Raw_data!A28="",NA(),Raw_data!A28) -> ORD0027 | B26: =IF(Raw_data!B28="",NA(),Raw_data!B28) -> 45840 | C26: =IF(Raw_data!C28="",NA(),Raw_data!C28) -> T-Shirt | D26: Electronics | E26: =IF(Raw_data!E28="",NA(),Raw_data!E28) -> 20 | F26: 3 | G26: =IF(Raw_data!G28="",NA(),Raw_data!G28) -> 20 | H26: =IF(Raw_data!H28="",NA(),Raw_data!H28) -> Daniel Harris | I26: =IF(Raw_data!I28="",NA(),Raw_data!I28) -> New York | J26: =IF(Raw_data!J28="",NA(),Raw_data!J28) -> Amazon Pay | K26: =IF(Raw_data!K28="",NA(),Raw_data!K28) -> Pending | L26: =COUNTIFS(A:A,A26,B:B,B26,C:C,C26,D:D,D26,E:E,E26,F:F,F26,G:G,G26,H:H,H26,I:I,I26,J:J,J26,K:K,K26) -> 1 | M26: =TEXT(B26,"dd-mm-yy") -> 02-07-25 | N26: =LEFT(Table2[[#This Row],[Date_text]],2) -> 02 | O26: =MID(Table2[[#This Row],[Date_text]],4,2) -> 07 | P26: =RIGHT(Table2[[#This Row],[Date_text]],2) -> 25
A27: =IF(Raw_data!A29="",NA(),Raw_data!A29) -> ORD0028 | B27: =IF(Raw_data!B29="",NA(),Raw_data!B29) -> 45718 | C27: =IF(Raw_data!C29="",NA(),Raw_data!C29) -> Headphones | D27: =IF(Raw_data!D29="",NA(),Raw_data!D29) -> Electronics | E27: =IF(Raw_data!E29="",NA(),Raw_data!E29) -> 100 | F27: =IF(Raw_data!F29="",NA(),Raw_data!F29) -> 1 | G27: =IF(Raw_data!G29="",NA(),Raw_data!G29) -> 100 | H27: =IF(Raw_data!H29="",NA(),Raw_data!H29) -> Jane Smith | ... K27: =IF(Raw_data!K29="",NA(),Raw_data!K29) -> Completed | L27: =COUNTIFS(A:A,A27,B:B,B27,C:C,C27,D:D,D27,E:E,E27,F:F,F27,G:G,G27,H:H,H27,I:I,I27,J:J,J27,K:K,K27) -> 1 | M27: =TEXT(B27,"dd-mm-yy") -> 02-03-25 | N27: =LEFT(Table2[[#This Row],[Date_text]],2) -> 02 | O27: =MID(Table2[[#This Row],[Date_text]],4,2) -> 03 | P27: =RIGHT(Table2[[#This Row],[Date_text]],2) -> 25
A28: =IF(Raw_data!A30="",NA(),Raw_data!A30) -> ORD0029 | B28: =IF(Raw_data!B30="",NA(),Raw_data!B30) -> 45993 | C28: =IF(Raw_data!C30="",NA(),Raw_data!C30) -> Smartphone | D28: =IF(Raw_data!D30="",NA(),Raw_data!D30) -> Electronics | E28: =IF(Raw_data!E30="",NA(),Raw_data!E30) -> 500 | F28: =IF(Raw_data!F30="",NA(),Raw_data!F30) -> 1 | G28: =IF(Raw_data!G30="",NA(),Raw_data!G30) -> 500 | H28: =IF(Raw_data!H30="",NA(),Raw_data!H30) -> Sophia Miller | ... K28: =IF(Raw_data!K30="",NA(),Raw_data!K30) -> Cancelled | L28: =COUNTIFS(A:A,A28,B:B,B28,C:C,C28,D:D,D28,E:E,E28,F:F,F28,G:G,G28,H:H,H28,I:I,I28,J:J,J28,K:K,K28) -> 1 | M28: =TEXT(B28,"dd-mm-yy") -> 02-12-25 | N28: =LEFT(Table2[[#This Row],[Date_text]],2) -> 02 | O28: =MID(Table2[[#This Row],[Date_text]],4,2) -> 12 | P28: =RIGHT(Table2[[#This Row],[Date_text]],2) -> 25
A29: =IF(Raw_data!A31="",NA(),Raw_data!A31) -> ORD0030 | B29: =IF(Raw_data!B31="",NA(),Raw_data!B31) -> 45932 | C29: =IF(Raw_data!C31="",NA(),Raw_data!C31) -> Washing Machine | D29: =IF(Raw_data!D31="",NA(),Raw_data!D31) -> Home Appliances | E29: =IF(Raw_data!E31="",NA(),Raw_data!E31) -> 600 | F29: =IF(Raw_data!F31="",NA(),Raw_data!F31) -> 3 | G29: =IF(Raw_data!G31="",NA(),Raw_data!G31) -> 1800 | H29: =IF(Raw_data!H31="",NA(),Raw_data!H31) -> Emily Johnson | ... K29: =IF(Raw_data!K31="",NA(),Raw_data!K31) -> Cancelled | L29: =COUNTIFS(A:A,A29,B:B,B29,C:C,C29,D:D,D29,E:E,E29,F:F,F29,G:G,G29,H:H,H29,I:I,I29,J:J,J29,K:K,K29) -> 1 | M29: =TEXT(B29,"dd-mm-yy") -> 02-10-25 | N29: =LEFT(Table2[[#This Row],[Date_text]],2) -> 02 | O29: =MID(Table2[[#This Row],[Date_text]],4,2) -> 10 | P29: =RIGHT(Table2[[#This Row],[Date_text]],2) -> 25
A30: =IF(Raw_data!A32="",NA(),Raw_data!A32) -> ORD0031 | B30: =IF(Raw_data!B32="",NA(),Raw_data!B32) -> 24-03-25 | C30: =IF(Raw_data!C32="",NA(),Raw_data!C32) -> Smartphone | D30: =IF(Raw_data!D32="",NA(),Raw_data!D32) -> Electronics | E30: 150 | F30: =IF(Raw_data!F32="",NA(),Raw_data!F32) -> 1 | G30: =IF(Raw_data!G32="",NA(),Raw_data!G32) -> 500 | H30: =IF(Raw_data!H32="",NA(),Raw_data!H32) -> John Doe | I30: =IF(Raw_data!I32="",NA(),Raw_data!I32) -> Houston | J30: =IF(Raw_data!J32="",NA(),Raw_data!J32) -> Gift Card | K30: =IF(Raw_data!K32="",NA(),Raw_data!K32) -> Pending | L30: =COUNTIFS(A:A,A30,B:B,B30,C:C,C30,D:D,D30,E:E,E30,F:F,F30,G:G,G30,H:H,H30,I:I,I30,J:J,J30,K:K,K30) -> 1 | M30: =TEXT(B30,"dd-mm-yy") -> 24-03-25 | N30: =LEFT(Table2[[#This Row],[Date_text]],2) -> 24 | O30: =MID(Table2[[#This Row],[Date_text]],4,2) -> 03 | P30: =RIGHT(Table2[[#This Row],[Date_text]],2) -> 25
A31: =IF(Raw_data!A33="",NA(),Raw_data!A33) -> ORD0032 | B31: =IF(Raw_data!B33="",NA(),Raw_data!B33) -> 45933 | C31: =IF(Raw_data!C33="",NA(),Raw_data!C33) -> Smartphone | D31: =IF(Raw_data!D33="",NA(),Raw_data!D33) -> Electronics | E31: =IF(Raw_data!E33="",NA(),Raw_data!E33) -> 500 | F31: =IF(Raw_data!F33="",NA(),Raw_data!F33) -> 4 | G31: =IF(Raw_data!G33="",NA(),Raw_data!G33) -> 2000 | H31: =IF(Raw_data!H33="",NA(),Raw_data!H33) -> Michael Brown | ... K31: =IF(Raw_data!K33="",NA(),Raw_data!K33) -> Pending | L31: =COUNTIFS(A:A,A31,B:B,B31,C:C,C31,D:D,D31,E:E,E31,F:F,F31,G:G,G31,H:H,H31,I:I,I31,J:J,J31,K:K,K31) -> 1 | M31: =TEXT(B31,"dd-mm-yy") -> 03-10-25 | N31: =LEFT(Table2[[#This Row],[Date_text]],2) -> 03 | O31: =MID(Table2[[#This Row],[Date_text]],4,2) -> 10 | P31: =RIGHT(Table2[[#This Row],[Date_text]],2) -> 25
A32: =IF(Raw_data!A35="",NA(),Raw_data!A35) -> ORD0034 | B32: =IF(Raw_data!B35="",NA(),Raw_data!B35) -> 45692 | C32: =IF(Raw_data!C35="",NA(),Raw_data!C35) -> T-Shirt | D32: =IF(Raw_data!D35="",NA(),Raw_data!D35) -> Clothing | E32: =IF(Raw_data!E35="",NA(),Raw_data!E35) -> 20 | F32: =IF(Raw_data!F35="",NA(),Raw_data!F35) -> 5 | G32: =IF(Raw_data!G35="",NA(),Raw_data!G35) -> 100 | H32: =IF(Raw_data!H35="",NA(),Raw_data!H35) -> Jane Smith | ... K32: =IF(Raw_data!K35="",NA(),Raw_data!K35) -> Pending | L32: =COUNTIFS(A:A,A32,B:B,B32,C:C,C32,D:D,D32,E:E,E32,F:F,F32,G:G,G32,H:H,H32,I:I,I32,J:J,J32,K:K,K32) -> 1 | M32: =TEXT(B32,"dd-mm-yy") -> 04-02-25 | N32: =LEFT(Table2[[#This Row],[Date_text]],2) -> 04 | O32: =MID(Table2[[#This Row],[Date_text]],4,2) -> 02 | P32: =RIGHT(Table2[[#This Row],[Date_text]],2) -> 25
A33: =IF(Raw_data!A36="",NA(),Raw_data!A36) -> ORD0035 | B33: =IF(Raw_data!B36="",NA(),Raw_data!B36) -> 45692 | C33: =IF(Raw_data!C36="",NA(),Raw_data!C36) -> Laptop | D33: =IF(Raw_data!D36="",NA(),Raw_data!D36) -> Electronics | E33: =IF(Raw_data!E36="",NA(),Raw_data!E36) -> 800 | F33: =IF(Raw_data!F36="",NA(),Raw_data!F36) -> 3 | G33: =IF(Raw_data!G36="",NA(),Raw_data!G36) -> 2400 | H33: =IF(Raw_data!H36="",NA(),Raw_data!H36) -> Emma Clark | ... K33: =IF(Raw_data!K36="",NA(),Raw_data!K36) -> Completed | L33: =COUNTIFS(A:A,A33,B:B,B33,C:C,C33,D:D,D33,E:E,E33,F:F,F33,G:G,G33,H:H,H33,I:I,I33,J:J,J33,K:K,K33) -> 1 | M33: =TEXT(B33,"dd-mm-yy") -> 04-02-25 | N33: =LEFT(Table2[[#This Row],[Date_text]],2) -> 04 | O33: =MID(Table2[[#This Row],[Date_text]],4,2) -> 02 | P33: =RIGHT(Table2[[#This Row],[Date_text]],2) -> 25
A34: =IF(Raw_data!A37="",NA(),Raw_data!A37) -> ORD0036 | B34: =IF(Raw_data!B37="",NA(),Raw_data!B37) -> 45902 | C34: =IF(Raw_data!C37="",NA(),Raw_data!C37) -> Refrigerator | D34: =IF(Raw_data!D37="",NA(),Raw_data!D37) -> Home Appliances | E34: =IF(Raw_data!E37="",NA(),Raw_data!E37) -> 1200 | F34: =IF(Raw_data!F37="",NA(),Raw_data!F37) -> 2 | G34: =IF(Raw_data!G37="",NA(),Raw_data!G37) -> 2400 | H34: =IF(Raw_data!H37="",NA(),Raw_data!H37) -> Sophia Miller | ... K34: =IF(Raw_data!K37="",NA(),Raw_data!K37) -> Cancelled | L34: =COUNTIFS(A:A,A34,B:B,B34,C:C,C34,D:D,D34,E:E,E34,F:F,F34,G:G,G34,H:H,H34,I:I,I34,J:J,J34,K:K,K34) -> 1 | M34: =TEXT(B34,"dd-mm-yy") -> 02-09-25 | N34: =LEFT(Table2[[#This Row],[Date_text]],2) -> 02 | O34: =MID(Table2[[#This Row],[Date_text]],4,2) -> 09 | P34: =RIGHT(Table2[[#This Row],[Date_text]],2) -> 25
A35: =IF(Raw_data!A38="",NA(),Raw_data!A38) -> ORD0037 | B35: =IF(Raw_data!B38="",NA(),Raw_data!B38) -> 16-02-25 | C35: =IF(Raw_data!C38="",NA(),Raw_data!C38) -> Headphones | D35: =IF(Raw_data!D38="",NA(),Raw_data!D38) -> Electronics | E35: =IF(Raw_data!E38="",NA(),Raw_data!E38) -> 100 | F35: =IF(Raw_data!F38="",NA(),Raw_data!F38) -> 3 | G35: =IF(Raw_data!G38="",NA(),Raw_data!G38) -> 300 | H35: =IF(Raw_data!H38="",NA(),Raw_data!H38) -> Michael Brown | ... K35: =IF(Raw_data!K38="",NA(),Raw_data!K38) -> Cancelled | L35: =COUNTIFS(A:A,A35,B:B,B35,C:C,C35,D:D,D35,E:E,E35,F:F,F35,G:G,G35,H:H,H35,I:I,I35,J:J,J35,K:K,K35) -> 1 | M35: =TEXT(B35,"dd-mm-yy") -> 16-02-25 | N35: =LEFT(Table2[[#This Row],[Date_text]],2) -> 16 | O35: =MID(Table2[[#This Row],[Date_text]],4,2) -> 02 | P35: =RIGHT(Table2[[#This Row],[Date_text]],2) -> 25
A36: =IF(Raw_data!A39="",NA(),Raw_data!A39) -> ORD0038 | B36: =IF(Raw_data!B39="",NA(),Raw_data!B39) -> 26-03-25 | C36: =IF(Raw_data!C39="",NA(),Raw_data!C39) -> Laptop | D36: =IF(Raw_data!D39="",NA(),Raw_data!D39) -> Electronics | E36: =IF(Raw_data!E39="",NA(),Raw_data!E39) -> 800 | F36: =IF(Raw_data!F39="",NA(),Raw_data!F39) -> 3 | G36: =IF(Raw_data!G39="",NA(),Raw_data!G39) -> 2400 | H36: =IF(Raw_data!H39="",NA(),Raw_data!H39) -> Olivia Wilson | ... K36: =IF(Raw_data!K39="",NA(),Raw_data!K39) -> Completed | L36: =COUNTIFS(A:A,A36,B:B,B36,C:C,C36,D:D,D36,E:E,E36,F:F,F36,G:G,G36,H:H,H36,I:I,I36,J:J,J36,K:K,K36) -> 1 | M36: =TEXT(B36,"dd-mm-yy") -> 26-03-25 | N36: =LEFT(Table2[[#This Row],[Date_text]],2) -> 26 | O36: =MID(Table2[[#This Row],[Date_text]],4,2) -> 03 | P36: =RIGHT(Table2[[#This Row],[Date_text]],2) -> 25
A37: =IF(Raw_data!A40="",NA(),Raw_data!A40) -> ORD0039 | B37: =IF(Raw_data!B40="",NA(),Raw_data!B40) -> 45691 | C37: =IF(Raw_data!C40="",NA(),Raw_data!C40) -> Laptop | D37: Electronics | E37: =IF(Raw_data!E40="",NA(),Raw_data!E40) -> 800 | F37: =IF(Raw_data!F40="",NA(),Raw_data!F40) -> 2 | G37: =IF(Raw_data!G40="",NA(),Raw_data!G40) -> 1600 | H37: =IF(Raw_data!H40="",NA(),Raw_data!H40) -> Olivia Wilson | I37: =IF(Raw_data!I40="",NA(),Raw_data!I40) -> San Francisco | J37: =IF(Raw_data!J40="",NA(),Raw_data!J40) -> PayPal | K37: =IF(Raw_data!K40="",NA(),Raw_data!K40) -> Completed | L37: =COUNTIFS(A:A,A37,B:B,B37,C:C,C37,D:D,D37,E:E,E37,F:F,F37,G:G,G37,H:H,H37,I:I,I37,J:J,J37,K:K,K37) -> 1 | M37: =TEXT(B37,"dd-mm-yy") -> 03-02-25 | N37: =LEFT(Table2[[#This Row],[Date_text]],2) -> 03 | O37: =MID(Table2[[#This Row],[Date_text]],4,2) -> 02 | P37: =RIGHT(Table2[[#This Row],[Date_text]],2) -> 25
A38: =IF(Raw_data!A41="",NA(),Raw_data!A41) -> ORD0040 | B38: =IF(Raw_data!B41="",NA(),Raw_data!B41) -> 26-03-25 | C38: =IF(Raw_data!C41="",NA(),Raw_data!C41) -> Smartwatch | D38: =IF(Raw_data!D41="",NA(),Raw_data!D41) -> Electronics | E38: =IF(Raw_data!E41="",NA(),Raw_data!E41) -> 150 | F38: =IF(Raw_data!F41="",NA(),Raw_data!F41) -> 1 | G38: =IF(Raw_data!G41="",NA(),Raw_data!G41) -> 150 | H38: =IF(Raw_data!H41="",NA(),Raw_data!H41) -> Emily Johnson | ... K38: =IF(Raw_data!K41="",NA(),Raw_data!K41) -> Pending | L38: =COUNTIFS(A:A,A38,B:B,B38,C:C,C38,D:D,D38,E:E,E38,F:F,F38,G:G,G38,H:H,H38,I:I,I38,J:J,J38,K:K,K38) -> 1 | M38: =TEXT(B38,"dd-mm-yy") -> 26-03-25 | N38: =LEFT(Table2[[#This Row],[Date_text]],2) -> 26 | O38: =MID(Table2[[#This Row],[Date_text]],4,2) -> 03 | P38: =RIGHT(Table2[[#This Row],[Date_text]],2) -> 25
A39: =IF(Raw_data!A42="",NA(),Raw_data!A42) -> ORD0041 | B39: =IF(Raw_data!B42="",NA(),Raw_data!B42) -> 20-02-25 | C39: =IF(Raw_data!C42="",NA(),Raw_data!C42) -> Book | D39: =IF(Raw_data!D42="",NA(),Raw_data!D42) -> Books | E39: =IF(Raw_data!E42="",NA(),Raw_data!E42) -> 15 | F39: =IF(Raw_data!F42="",NA(),Raw_data!F42) -> 1 | G39: =IF(Raw_data!G42="",NA(),Raw_data!G42) -> 15 | H39: =IF(Raw_data!H42="",NA(),Raw_data!H42) -> Jane Smith | ... K39: =IF(Raw_data!K42="",NA(),Raw_data!K42) -> Cancelled | L39: =COUNTIFS(A:A,A39,B:B,B39,C:C,C39,D:D,D39,E:E,E39,F:F,F39,G:G,G39,H:H,H39,I:I,I39,J:J,J39,K:K,K39) -> 1 | M39: =TEXT(B39,"dd-mm-yy") -> 20-02-25 | N39: =LEFT(Table2[[#This Row],[Date_text]],2) -> 20 | O39: =MID(Table2[[#This Row],[Date_text]],4,2) -> 02 | P39: =RIGHT(Table2[[#This Row],[Date_text]],2) -> 25
A40: =IF(Raw_data!A44="",NA(),Raw_data!A44) -> ORD0043 | B40: =IF(Raw_data!B44="",NA(),Raw_data!B44) -> 45871 | C40: =IF(Raw_data!C44="",NA(),Raw_data!C44) -> T-Shirt | D40: =IF(Raw_data!D44="",NA(),Raw_data!D44) -> Clothing | E40: 150 | F40: 3 | G40: =IF(Raw_data!G44="",NA(),Raw_data!G44) -> 80 | H40: =IF(Raw_data!H44="",NA(),Raw_data!H44) -> Jane Smith | I40: =IF(Raw_data!I44="",NA(),Raw_data!I44) -> Denver | J40: =IF(Raw_data!J44="",NA(),Raw_data!J44) -> Credit Card | K40: =IF(Raw_data!K44="",NA(),Raw_data!K44) -> Pending | L40: =COUNTIFS(A:A,A40,B:B,B40,C:C,C40,D:D,D40,E:E,E40,F:F,F40,G:G,G40,H:H,H40,I:I,I40,J:J,J40,K:K,K40) -> 1 | M40: =TEXT(B40,"dd-mm-yy") -> 02-08-25 | N40: =LEFT(Table2[[#This Row],[Date_text]],2) -> 02 | O40: =MID(Table2[[#This Row],[Date_text]],4,2) -> 08 | P40: =RIGHT(Table2[[#This Row],[Date_text]],2) -> 25
...

Sheet Data_analysis
A3: Category | B3: Total_Sales | D3: Category | E3: Quantity_ | G3: Price | H3: Distribution | J3: Status | K3: Total Status | M3: Category | N3: Total_Sales | O3: Quantity_ | Q3: KPIS | R3: Column1
A4: Electronics | B4: 124115 | D4: Electronics | E4: 332 | G4: 15-34 | H4: 37 | J4: Can | K4: 64 | M4: Books | N4: 900 | O4: 60 | Q4: GMV | R4: =SUM(Cleanning_data!G2:G220) -> 212815
A5: Home Appliances | B5: 81600 | D5: Clothing | E5: 90 | G5: 35-54 | H5: 15 | J5: Com | K5: 78 | M5: Book | N5: 900 | O5: 60 | Q5: Total order | R5: =SUM(Cleanning_data!F2:F220) -> 629
A6: Footwear | B6: 3540 | D6: Home Appliances | E6: 88 | G6: 55-74 | H6: 24 | J6: pen | K6: 76 | M6: Clothing | N6: 2660 | O6: 90 | Q6: AOV | R6: =ROUND(R4/R5,2) -> 338.34
A7: Clothing | B7: 2660 | D7: Books | E7: 60 | G7: 95-114 | H7: 21 | J7: Grand Total | K7: 218 | M7: Jeans | N7: 1680 | O7: 42
A8: Books | B8: 900 | D8: Footwear | E8: 59 | G8: 135-154 | H8: 45 | M8: T-Shirt | N8: 980 | O8: 48
A9: Grand Total | B9: 212815 | D9: Grand Total | E9: 629 | G9: 495-514 | H9: 24 | J9: Payment Method | K9: Total Payment Method | M9: Electronics | N9: 124115 | O9: 332
G10: 595-614 | H10: 14 | J10: Amazon Pay | K10: 34 | M10: Book | N10: 45 | O10: 3
A11: Product | B11: Total_sales | D11: Product | E11: Quantity_ | G11: 795-814 | H11: 21 | J11: Credit Card | K11: 49 | M11: Headphones | N11: 6000 | O11: 62
A12: Refrigerator | B12: 64800 | D12: Smartwatch | E12: 99 | G12: 1195-1214 | H12: 17 | J12: Debit Card | K12: 47 | M12: Jeans | N12: 280 | O12: 7
A13: Laptop | B13: 56000 | D13: Smartphone | E13: 78 | G13: Grand Total | H13: 218 | J13: Gift Card | K13: 36 | M13: Laptop | N13: 56000 | O13: 71
A14: Smartphone | B14: 39000 | D14: Laptop | E14: 71 | J14: PayPal | K14: 52 | M14: Refrigerator | N14: 7200 | O14: 6
A15: Washing Machine | B15: 24600 | D15: Book | E15: 63 | G15: Quantity | H15: Distribution | J15: Grand Total | K15: 218 | M15: Running Shoes | N15: 120 | O15: 2
A16: Smartwatch | B16: 14850 | D16: Headphones | E16: 62 | G16: 1-1 | H16: 46 | M16: Smartphone | N16: 39000 | O16: 78
A17: Headphones | B17: 6000 | D17: Running Shoes | E17: 61 | G17: 2-2 | H17: 43 | M17: Smartwatch | N17: 14850 | O17: 99
A18: Running Shoes | B18: 3660 | D18: Refrigerator | E18: 56 | G18: 3-3 | H18: 59 | M18: T-Shirt | N18: 20 | O18: 3
A19: Jeans | B19: 1960 | D19: T-Shirt | E19: 51 | G19: 4-5 | H19: 70 | M19: Washing Machine | N19: 600 | O19: 1
A20: T-Shirt | B20: 1000 | D20: Jeans | E20: 49 | G20: Grand Total | H20: 218 | M20: Footwear | N20: 3540 | O20: 59
A21: Book | B21: 945 | D21: Washing Machine | E21: 39 | M21: Running Shoes | N21: 3540 | O21: 59
A22: Grand Total | B22: 212815 | D22: Grand Total | E22: 629 | G22: Total Sales | H22: Distribution | M22: Home Appliances | N22: 81600 | O22: 88
G23: 15-114 | H23: 56 | M23: Refrigerator | N23: 57600 | O23: 50
A24: Location | B24: Total_sales | D24: Location | E24: Quantity_ | G24: 115-214 | H24: 30 | M24: Washing Machine | N24: 24000 | O24: 38
A25: Denver | B25: 29635 | D25: Denver | E25: 78 | G25: 215-314 | H25: 22 | M25: Grand Total | N25: 212815 | O25: 629
A26: Miami | B26: 28600 | D26: Miami | E26: 74 | G26: 315-414 | H26: 5
A27: Boston | B27: 25170 | D27: New York | E27: 70 | G27: 415-514 | H27: 16
A28: Houston | B28: 24380 | D28: Houston | E28: 70 | G28: 515-614 | H28: 8
A29: Dallas | B29: 19605 | D29: Boston | E29: 67 | G29: 715-814 | H29: 11
A30: New York | B30: 18665 | D30: Dallas | E30: 67 | G30: 915-1014 | H30: 6
A31: Chicago | B31: 17655 | D31: San Francisco | E31: 59 | G31: 1115-1214 | H31: 6
A32: Seattle | B32: 17490 | D32: Seattle | E32: 50 | G32: 1415-1514 | H32: 6
A33: Los Angeles | B33: 17020 | D33: Chicago | E33: 49 | G33: 1515-1614 | H33: 2
A34: San Francisco | B34: 14595 | D34: Los Angeles | E34: 45 | G34: 1715-1814 | H34: 3
A35: Grand Total | B35: 212815 | D35: Grand Total | E35: 629 | G35: 1915-2014 | H35: 5
G36: 2315-2414 | H36: 17
A37: Customer Name | B37: Total_sales | D37: Customer Name | E37: Quantity_ | G37: 2415-2514 | H37: 4
A38: Sophia Miller | B38: 8395 | D38: Emma Clark | E38: 90 | G38: 2915-3014 | H38: 2
A39: Daniel Harris | B39: 16495 | D39: Jane Smith | E39: 76 | G39: 3115-3214 | H39: 4
A40: Emily Johnson | B40: 17775 | D40: Olivia Wilson | E40: 74 | G40: 3515-3614 | H40: 5
A41: Chris White | B41: 18585 | D41: Michael Brown | E41: 70 | G41: 3915-4014 | H41: 4
A42: David Lee | B42: 20025 | D42: David Lee | E42: 60 | G42: 4715-4814 | H42: 4
...

Sheet Dashboard_tab1

Sheet Dashboard_tab2

Sheet Insights_and_Recomendations
A1: INSIGHT
A2: * Doanh thu tăng mạnh ở tháng 2 và tháng 3 với lần lượt doanh thu là 66750$ và 71330$, doanh thu tháng 2 và tháng 3 chiếm 65% tổng số doanh thu, trong khi đó doanh số giảm mạnh ở tháng 1 với doanh thu là 520$ trong khi các tháng khác doanh thu đều trên 2000$
A3: * Trong 5 nhóm sản phẩm mà công ty đang kinh doanh, hai nhóm sản phẩm mang lại doanh thu tốt nhất là Electronics và Home appliances với doanh thu lần lượt là 124115$ chiếm 58% tổng doanh thu và 81600$ chiếm 38,3% tổng doanh thu, riêng hai nhóm sản phẩm này đã chiếm hơn 96% tổng doanh thu, 3 nhóm sản phẩm còn lại là Footwear, clothing và books mang lại doanh thu rất thấp dao động từ 900$ - dưới 3000$, cả ba nhóm sản phẩm này mới chiếm đến 4% tổng doanh thu
A4: * Ba sản phẩm mà công ty đang kinh doanh tốt nhất là Refrigerator, Laptop và Smartphone, với lần lượt doanh thu là 64800,56000 và 39000. Ba sản phẩm phẩm đang có tình hình kinh doanh tệ nhất là Book, T-shift và running shoes với doanh thu lần lượt là 945$, 1000$ và 1960$
A5: * Top 3 khách hàng mua hàng nhiều nhất là Olivia Wilson, Emma Clark và Jane Smith với số tiền mua lần lượt là 32640$, 29400$ và 26885$
A6: * Tỷ lệ chờ để xử lý đơn hàng (trạng thái pend) rất cao lên đến 35%, tỷ lệ hủy hàng rất cao lên đến 30% điều đó dẫn đến tỷ lệ hoàn thành đơn hàng chỉ có 35% đây là con số rất thấp, điều này cho thấy hệ thống xử lý đơn hàng đang hoạt động rất kém hiệu quả, trong thương mại điện tử con số đạt yêu cầu là tỷ lệ hoàn thành đơn hàng phải trên 90% và tỷ lệ hủy và pend chỉ ở mức dưới 5%
A7: * Tỷ lẹ các thương thức thanh toán tương đương nhau, chênh nhau không quá nhiều cho thấy rằng khách hàng họ không ưu tiên sử dụng một phương thức thanh toán cụ thể nào cả, mà đa dạng về phương thức thanh toán
A8: * Doanh số tại các khu vực theo từng bang tương đương nhau, chênh lệch khá thấp, không có 1 bang nào vượt lên về doanh số, điều này cho thấy khách hàng của công ty phân bố và trải dài trên khắp tất cả các bang chứ không tạp trung riêng tại 1 bang nào cả
A9: * Các giao dịch mua hàng phần lớn có giá giao động từ 15$-300$, và nhiều nhất ở mức 15-100$,chỉ nguyên giao dịch ở khoảng 15$-300$ đã chiếm hơn 50% tổng số giao dịch, trên 300$ là các giao dịch giảm đi đang kể
A10: * Phân phối về giá sản phẩm thì đa dạng hơn, nó không tập chung nhiều tại 1 khoảng như giá giao dịch mà trải dài từ 15$ đến 1200$, có 1 số điểm nhiều hơn rõ ràng là ở mức 15$-34$ và 125$-154$ điều này là dễ hiểu vì nhìn vào sản lượng bán thì chủ yếu công ty bán được các sản phẩm Electronic và Home apliance nên là hai khoảng này hiều hơn là điều bình thường, còn lại giá sản phẩm trải dài từ 34$-1000$
A11: * Tổng sản lượng bán của home appliances và clothing đều chiếm khoảng 30% tổng sản lượng bán (88 và 90), thậm chí home appliances còn kém clothing 2 sản phẩm, tuy nhiên doanh thu của Home appliances lại chiếm đến gần 40% tổng doanh thu trong khi clothing chỉ chiếm có 1,2% tổng doanh số, điều này là bất thường vì đặc thù giá sản phẩm của cả đồ gia dụng và quần áo dều tương tương nhau thậm chí quần áo còn có giá cao hơn, điều này cho thấy tỷ lệ chuyển đổi của nhóm sản phẩm clothing là rất thấp
A13: RECOMENDATIONS
... A19: * Tháng 2 và tháng 3 doanh số tăng mạnh rất đáng ấn tượng, tuy nhiên doanh số các tháng khác thì lại rất thấp, doanh số tháng 1 thậm chí còn dưới 1000$, điều này là ko hợp lý vì sản phẩm của công ty là sản phẩm bán quanh năm, không phải loại sản phẩm bán theo màu vụ, cần nghiên cứu lại về thị trường, các chiến dịch marketing, để đảm bảo doanh số tăng đều phát triển bền vững
